2024-08-18 11:56:37,685 - exception_logger - ERROR - An exception occurred
Traceback (most recent call last):
  File "/tmp/ipykernel_3923/3259282278.py", line 12, in log_exception
    1 / 0
    ~~^~~
ZeroDivisionError: division by zero
